Workbook

Sheet Cover
B2: Operating Model Assessment Toolkit
B3: CTO Consulting | Business Analysis Practice
B4: ="Client: "&IF(Engagement!C5="","[enter on the Engagement tab]",Engagement!C5)&" | Status: "&Engagement!C14 -> Client: [enter on the Engagement tab] | Status: Mobilising
B6: Purpose
B7: A structured toolkit for an exhaustive assessment of how an organisation delivers value: its strategy, customers, services, processes, capabilities, structure, governance, people, culture, performance management, technology, data, suppliers, locations, risk and compliance, finances and change capability. It combines a 157-question maturity diagnostic across 17 dimensions with the planning tools, current-state inventories, analysis and outputs needed to move from evidence to a prioritised set of recommendations.
B9: How to use this workbook
B10: 1. Mobilise | C10: Complete the Engagement tab: client details, objectives, scope, hypotheses, design principles and assessment settings.
B11: 2. Plan | C11: Register stakeholders, tailor the Interview Guides and issue the Document Requests list.
B12: 3. Discover | C12: Run interviews and workshops, review documents and populate the current-state inventories (Capabilities, Processes, Org Structure, Decision Rights, Applications, Suppliers, Locations, Cost Baseline).
B13: 4. Assess | C13: Score each question on the Assessment tab (current and target maturity, 1–5 or N/A) against the Maturity Model and 'What good looks like'. Record the evidence reviewed and your confidence in it.
B14: 5. Analyse | C14: Log findings and root causes on the Findings tab, validate them with stakeholders and review the Dashboard.
B15: 6. Recommend | C15: Describe the current and target state and key shifts on Current vs Target; log, score and sequence recommendations.
B16: 7. Tailor | C16: Add questions by inserting rows inside a dimension block and copying the formulas down. Dropdown values and span benchmarks are maintained on the Lists tab.
B18: Workbook map
B19: Phase | C19: Tab | D19: Purpose
B20: Set up | C20: Engagement | D20: Client details, objectives, scope, hypotheses, design principles and assessment settings.
B21: Reference | C21: Framework | D21: The 17 dimensions, definitions and mapping to recognised frameworks, plus the assessment approach.
B22: Reference | C22: Maturity Model | D22: Five-level maturity descriptors for each dimension.
B23: Plan | C23: Stakeholders | D23: Stakeholder register, influence and interest, and interview schedule.
B24: Plan | C24: Interview Guides | D24: Interview questions for ten stakeholder groups, mapped to dimensions.
B25: Plan | C25: Document Requests | D25: 69 pre-populated document and data requests with tracking.
B26: Discover & assess | C26: Assessment | D26: 157-question maturity diagnostic with evidence, confidence, gap and RAG.
B27: Discover & assess | C27: Capabilities | D27: Level 1 / Level 2 business capability map with importance, maturity and priority heat map.
B28: Discover & assess | C28: Processes | D28: Value streams and processes with documentation, automation and performance data.
B29: Discover & assess | C29: Org Structure | D29: Workforce mix, spans of control, layers and cost by business unit.
B30: Discover & assess | C30: Decision Rights | D30: RAPID matrix for key decisions with checks for missing or multiple deciders.
... B39: Reference | C39: Lists | D39: Dropdown values, span-of-control benchmarks and importance weights.
B41: Cell legend
B42: Input | C42: Enter or select a value (dropdowns where shown).
B43: Calculated | C43: Formula. Do not overwrite.
B44: Linked | C44: Pulled from another tab (green text).
B45: Example row | C45: Shows the expected format. Overwrite or delete; excluded from totals and the Dashboard.
B46: Reference content | C46: Pre-populated guidance. Tailor to the client where needed.
B48: Maturity scale
B49: 1 – Initial | C49: Ad hoc, undocumented and person-dependent. Outcomes are unpredictable and largely reactive.
B50: 2 – Developing | C50: Some practices are defined but applied inconsistently. Limited measurement; still largely reactive.
B51: 3 – Defined | C51: Practices are documented, standardised and applied consistently across the organisation.
B52: 4 – Managed | C52: Practices are measured and actively managed against targets. Decisions are data-driven.
B53: 5 – Optimised | C53: Continuous improvement is embedded. Leading practice that adapts quickly to change.
B54: N/A – Not applicable | C54: Not relevant to this organisation or outside the agreed scope. Excluded from averages.
...

Sheet Engagement
B1: Engagement Details
B2: Complete this tab first. Settings in the Assessment settings table drive formulas across the workbook.
B4: Engagement details
B5: Client organisation
B6: Industry / sector
B7: Engagement name
B8: Client sponsor
B9: CTO Consulting engagement lead
B10: Assessment team
B11: Start date
B12: Target completion date
B13: Workbook version | C13: 0.1
B14: Engagement status | C14: Mobilising
B16: Engagement objectives
B17: Objective 1
B18: Objective 2
B19: Objective 3
B20: Objective 4
B21: Objective 5
B23: Scope
B24: In-scope business units / functions
B25: In-scope locations / geographies
B26: Dimensions in scope | C26: All 17 dimensions
B27: Out of scope
B28: Key constraints and assumptions
B30: Key hypotheses to test
B31: Hypothesis 1
B32: Hypothesis 2
B33: Hypothesis 3
B34: Hypothesis 4
B35: Hypothesis 5
B37: Assessment settings
B38: Setting | C38: Value | D38: How it is used
B39: Default target maturity (1–5) | C39: 3 | D39: Pre-fills the Target Maturity column on the Assessment tab. Overwrite individual questions where the target differs.
B40: RAG: Red when maturity gap is at least | C40: 1.5 | D40: Gap = target minus current. Applied to questions and dimension averages.
B41: RAG: Amber when maturity gap is at least | C41: 0.75 | D41: Gaps below this threshold are Green.
B42: Prioritisation threshold (Value and Ease, 1–5) | C42: 3 | D42: Recommendations with Value and Ease at or above this score are Quick wins; high Value / low Ease are Strategic initiatives.
B43: Maximum management layers (CEO = layer 1) | C43: 6 | D43: Org Structure flags business units whose deepest reporting line exceeds this.
B44: Contract / lease / support expiry warning (days) | C44: 180 | D44: Flags suppliers, leases and applications approaching expiry.
B45: Application TIME fit threshold (1–5) | C45: 3 | D45: Business and technical fit at or above this are 'high' when classifying applications as Tolerate, Invest, Migrate or Eliminate.
...

Sheet Framework
A1: Operating Model Framework
A2: 17 dimensions synthesised from the Operating Model Canvas (POLISM), McKinsey 7S, the Galbraith Star Model and TOGAF / BIZBOK business architecture.
A4: Code | B4: Dimension | C4: Definition | D4: Key sub-components assessed | E4: Key question answered | F4: Operating Model Canvas | G4: McKinsey 7S | H4: Galbraith Star | I4: TOGAF / BIZBOK | J4: Standards & references | K4: Questions (#)
A5: D01 | B5: Strategy & Direction | C5: The organisation's purpose, strategic objectives and the explicit choices the operating model must enable. | D5: Purpose and vision; strategic objectives; strategic choices; external environment; design principles; strategy-to-execution alignment; ESG | E5: Is it clear what the operating model must deliver, and are the strategic choices explicit? | F5: Value proposition (context for all elements) | G5: Strategy; Shared values | H5: Strategy | I5: Business motivation (drivers, goals, objectives) | J5: Balanced Scorecard; PESTLE / SWOT; Playing to Win; ASX Corporate Governance Principles | K5: =COUNTIF(Assessment!$B$6:$B$179,B5) -> 9
A6: D02 | B6: Customers, Channels & Value Proposition | C6: Who the organisation serves, what value it offers each segment, and how customers access and experience its services. | D6: Segments; value proposition; customer journeys; channel strategy; omnichannel consistency; voice of customer; service standards; accessibility | E6: Does the organisation understand and consistently deliver what its customers value, through the right channels? | F6: Value delivery chain (beneficiaries) | G6: Strategy | H6: Strategy | I6: Business architecture (actors, stakeholders, business services) | J6: Service design; NPS / CSAT / CES; WCAG 2.2; BIZBOK stakeholder mapping | K6: =COUNTIF(Assessment!$B$6:$B$179,B6) -> 9
A7: D03 | B7: Products & Services | C7: The portfolio of products and services the organisation delivers, and how that portfolio is owned, managed and evolved. | D7: Service catalogue; portfolio performance; ownership; lifecycle; complexity; innovation pipeline; pricing and funding; product obligations | E7: Is the portfolio of products and services clear, owned and actively managed for value? | F7: Value delivery chain | G7: Strategy | H7: Strategy | I7: Business services / products | J7: Product lifecycle management; ITIL 4 service catalogue; ASIC design and distribution obligations (where applicable) | K7: =COUNTIF(Assessment!$B$6:$B$179,B7) -> 8
A8: D04 | B8: Value Streams & Processes | C8: The end-to-end value streams and business processes through which work flows to deliver outcomes. | D8: Value streams; process architecture; ownership; documentation; standardisation; efficiency; automation; performance; hand-offs; embedded controls | E8: Does work flow efficiently, consistently and under control from trigger to outcome? | F8: Processes (value delivery chain) | G8: Systems | H8: Processes | I8: Business process; BIZBOK value streams | J8: APQC Process Classification Framework; BPMN 2.0; Lean; Six Sigma; process mining | K8: =COUNTIF(Assessment!$B$6:$B$179,B8) -> 10
A9: D05 | B9: Business Capabilities | C9: What the organisation must be able to do (independent of how), and the maturity of those abilities across people, process, technology and information. | D9: Capability map; strategic importance; maturity; ownership; investment alignment; gaps; duplication; sourcing | E9: Does the organisation have the capabilities its strategy needs, and is investment focused on the right ones? | F9: Processes; Organisation | G9: Skills; Systems | H9: Processes | I9: BIZBOK capability map; TOGAF capability-based planning | J9: BIZBOK Guide; TOGAF Standard 10th Edition | K9: =COUNTIF(Assessment!$B$6:$B$179,B9) -> 8
A10: D06 | B10: Organisation Structure & Roles | C10: How people and work are grouped, the reporting lines, spans and layers, and the clarity of roles and accountabilities. | D10: Structural archetype; spans of control; layers; centralisation vs devolution; shared services and CoEs; role clarity; duplication; interfaces; agility | E10: Is the structure aligned to strategy, lean, and clear about who is accountable for what? | F10: Organisation | G10: Structure | H10: Structure | I10: Organisation units; roles and actors | J10: Spans and layers analysis; organisation design archetypes | K10: =COUNTIF(Assessment!$B$6:$B$179,B10) -> 9
A11: D07 | B11: Governance & Decision Rights | C11: The bodies, delegations, policies and decision rights that direct and control the organisation. | D11: Governance framework; committee effectiveness; delegations; decision rights; decision speed; policy framework; oversight; three lines; transparency | E11: Are decisions made by the right people, at the right level, in a timely and accountable way? | F11: Management system | G11: Systems; Structure | H11: Structure; Processes | I11: Governance (architecture and enterprise) | J11: ASX Corporate Governance Principles; PGPA Act 2013 (Commonwealth entities); COBIT 2019; IIA Three Lines Model; RAPID / RACI | K11: =COUNTIF(Assessment!$B$6:$B$179,B11) -> 9
A12: D08 | B12: People, Workforce & Skills | C12: The size, mix, skills, capacity and management of the workforce needed to deliver the operating model. | D12: Workforce planning; workforce mix; capacity; skills; critical roles and succession; attraction and retention; performance; reward; WHS; engagement | E12: Does the organisation have the right people, with the right skills, in the right numbers, at the right cost? | F12: Organisation | G12: Staff; Skills | H12: People; Rewards | I12: Roles and actors | J12: Strategic workforce planning; SFIA (digital skills); Work Health and Safety Act 2011 and psychosocial hazard regulations | K12: =COUNTIF(Assessment!$B$6:$B$179,B12) -> 10
A13: D09 | B13: Culture, Leadership & Behaviours | C13: The shared values, leadership style and everyday behaviours that determine how work actually gets done. | D13: Values and behaviours; culture diagnosis; leadership; accountability; collaboration; customer centricity; psychological safety; risk culture; change readiness | E13: Do culture and leadership enable, or undermine, the intended operating model? | F13: Organisation; Management system | G13: Style; Shared values | H13: People; Rewards | I13: Not explicitly covered | J13: Culture diagnostics; 360-degree feedback; risk culture assessments | K13: =COUNTIF(Assessment!$B$6:$B$179,B13) -> 9
A14: D10 | B14: Performance Management & Planning | C14: How the organisation plans, sets targets, measures performance and uses information to steer. | D14: Planning cycle; KPI framework; cascade; management reporting; performance forums; target setting; incentive alignment; data for performance; external reporting | E14: Does the organisation know how it is performing and act on that information? | F14: Management system | G14: Systems | H14: Processes; Rewards | I14: Business motivation (measures) | J14: Balanced Scorecard; OKRs; integrated planning | K14: =COUNTIF(Assessment!$B$6:$B$179,B14) -> 9
A15: D11 | B15: Technology & Applications | C15: The applications, infrastructure, architecture and technology operating model that enable the business. | D15: Technology strategy; enterprise architecture; application portfolio; technical debt; infrastructure and cloud; integration; IT operating model; ITSM; digital, automation and AI; tech investment; end-user tools | E15: Is technology fit for purpose today, and an enabler rather than a constraint for the future? | F15: Information (systems) | G15: Systems | H15: Processes | I15: Application and technology architecture | J15: TOGAF; ITIL 4; COBIT 2019; Gartner TIME model; FinOps; Technology Business Management (TBM) | K15: =COUNTIF(Assessment!$B$6:$B$179,B15) -> 11
A16: D12 | B16: Data, Information & Analytics | C16: How data and information are governed, managed, protected and used to generate insight. | D16: Data strategy; data governance; data quality; master data; analytics; records management; privacy; classification; AI readiness | E16: Is data trusted, protected and used as an asset for decision making? | F16: Information | G16: Systems | H16: Processes | I16: Data architecture | J16: DAMA-DMBOK; Privacy Act 1988 and Australian Privacy Principles; ISO 15489 records management; ISO/IEC 42001 (AI management) | K16: =COUNTIF(Assessment!$B$6:$B$179,B16) -> 9
... A21: D17 | B21: Change, Transformation & Continuous Improvement | C21: The organisation's ability to prioritise, deliver and embed change and to improve continuously. | D21: Portfolio management; delivery methodology; delivery performance; change capacity; change management; benefits realisation; business analysis; continuous improvement; innovation; lessons learned | E21: Can the organisation move from its current to its target operating model and sustain the change? | F21: Management system | G21: Systems; Skills; Style | H21: Processes; People | I21: Implementation and migration (ADM phases E–G) | J21: PRINCE2; MSP; P3O; Agile / SAFe; Prosci ADKAR; BABOK v3; Lean | K21: =COUNTIF(Assessment!$B$6:$B$179,B21) -> 10
A24: Assessment approach
A25: Phase | C25: Key activities | D25: Workbook tabs | E25: Outputs
A26: 1. Mobilise | C26: Confirm objectives, scope, sponsor and success criteria. Identify stakeholders, issue the document request and schedule interviews. Agree design principles and assessment settings. | D26: Engagement; Stakeholders; Document Requests | E26: Engagement charter; stakeholder map; document request
A27: 2. Discover | C27: Review documents and data; run interviews, workshops and site visits; build the capability, process, organisation, decision rights, application, supplier, location and cost baselines. | D27: Interview Guides; Capabilities; Processes; Org Structure; Decision Rights; Applications; Suppliers; Locations; Cost Baseline | E27: Evidence base; current-state inventories and baselines
A28: 3. Assess & analyse | C28: Score current and target maturity for every question with evidence and confidence ratings. Identify findings and root causes and validate them with stakeholders. | D28: Assessment; Findings; Dashboard | E28: Maturity profile; validated findings; heat maps
A29: 4. Design & recommend | C29: Describe the target state and key shifts for each dimension against the design principles. Develop and prioritise recommendations by value and ease. | D29: Current vs Target; Recommendations | E29: Target operating model directions; prioritised recommendations
A30: 5. Roadmap & mobilise | C30: Sequence recommendations into horizons, confirm dependencies, owners and indicative costs, and present to the sponsor and executive. | D30: Recommendations; Dashboard | E30: Implementation roadmap; executive presentation

Sheet Maturity Model
A1: Maturity Model
A2: Descriptors for each maturity level by dimension. Use these, together with 'What good looks like' on the Assessment tab, to calibrate scores.
A4: Code | B4: Dimension | C4: 1 – Initial | D4: 2 – Developing | E4: 3 – Defined | F4: 4 – Managed | G4: 5 – Optimised
A5: All | B5: Generic scale (applies to every dimension) | C5: Ad hoc, undocumented and person-dependent. Outcomes are unpredictable and largely reactive. | D5: Some practices are defined but applied inconsistently. Limited measurement; still largely reactive. | E5: Practices are documented, standardised and applied consistently across the organisation. | F5: Practices are measured and actively managed against targets. Decisions are data-driven. | G5: Continuous improvement is embedded. Leading practice that adapts quickly to change.
A6: D01 | B6: Strategy & Direction | C6: No articulated strategy, or it exists only in the heads of a few leaders. Priorities shift frequently. | D6: Strategy documented but high level. Objectives are unclear or unprioritised; awareness is limited beyond the executive. | E6: Clear strategy with measurable objectives and agreed design principles, cascaded into business plans. | F6: Strategy drives portfolio, budget and operating model decisions. Progress reviewed quarterly and adjusted. | G6: Adaptive, evidence-led strategy informed by continuous scanning. The whole organisation understands and contributes to it.
A7: D02 | B7: Customers, Channels & Value Proposition | C7: Limited understanding of customers. Services are designed around internal structures. | D7: Basic segmentation. Feedback is collected but rarely acted upon; channels are managed in silos. | E7: Defined segments, value propositions and key journeys. Channel strategy and voice-of-customer program in place. | F7: Journeys owned and measured end to end. Consistent omnichannel experience; insight drives service change. | G7: Customer-centric by design. Predictive insight personalises services and customers co-design improvements.
A8: D03 | B8: Products & Services | C8: No complete view of products and services. Ownership is unclear. | D8: Catalogue exists but is incomplete. Performance data is partial and launches are ad hoc. | E8: Complete catalogue with owners, a defined lifecycle process and tracked performance. | F8: Portfolio actively managed on value and cost, with regular rationalisation and a strategy-linked pipeline. | G8: Portfolio continuously optimised using customer and financial insight; rapid test-and-learn development.
A9: D04 | B9: Value Streams & Processes | C9: Processes are undocumented and person-dependent, with high variation and rework. | D9: Some processes documented. Ownership is functional and measurement is limited. | E9: Process architecture defined. Key processes documented, owned and measured with KPIs. | F9: End-to-end process owners manage performance. Processes are standardised and automation is applied systematically. | G9: Processes continuously optimised using data (e.g. process mining), with intelligent automation at scale.
A10: D05 | B10: Business Capabilities | C10: No capability view. Investment is decided project by project. | D10: A capability map has been drafted but is not used in decision making. | E10: Endorsed capability map with named owners and a maturity assessment. | F10: Capability-based planning drives investment, architecture and sourcing decisions. | G10: The capability model is the common language for strategy, architecture, investment and performance.
A11: D06 | B11: Organisation Structure & Roles | C11: Structure has evolved organically. Roles are unclear and duplication is significant. | D11: Structure documented with some role clarity. Spans and layers have not been analysed. | E11: Structure aligned to strategy with a documented rationale. Roles defined; spans and layers within broad norms. | F11: Structure optimised (spans, layers, shared services) and reviewed regularly, with strong cross-unit interfaces. | G11: Adaptive structure that reconfigures around priorities with minimal disruption.
A12: D07 | B12: Governance & Decision Rights | C12: Governance is informal. Decisions are escalated or made inconsistently; delegations are out of date. | D12: Committees exist but overlap. Decision rights are unclear and delegations are poorly understood. | E12: Governance framework and delegations defined. Committees have terms of reference; key decision rights are defined. | F12: Governance is effective and efficient. Decisions are timely and made at the right level; the three lines operate well. | G12: Governance is continuously reviewed. Decision making is agile, transparent and data-driven.
A13: D08 | B13: People, Workforce & Skills | C13: Workforce management is reactive, with limited workforce data. | D13: Basic workforce reporting. Skills gaps are known anecdotally and development is ad hoc. | E13: Workforce plan and skills framework in place. Performance and development processes are consistent. | F13: Strategic workforce planning is integrated with business planning. Talent is actively managed; engagement is high. | G13: Predictive workforce analytics and agile deployment of talent. Recognised employer of choice.
A14: D09 | B14: Culture, Leadership & Behaviours | C14: Values are not defined or not lived. Trust is low and behaviours are siloed. | D14: Values are defined but inconsistently demonstrated. Culture is not measured. | E14: Culture is measured and the desired shifts are defined. Leadership development is in place. | F14: Leaders role-model desired behaviours. Culture is reinforced through hiring, reward and recognition. | G14: Culture is a source of advantage, with high psychological safety and continuous learning.
A15: D10 | B15: Performance Management & Planning | C15: Few or no KPIs. Reporting is ad hoc and manual. | D15: KPIs exist but are mainly financial or activity-based. Reporting is lagging and manual. | E15: Balanced KPI framework cascaded through the organisation. Integrated planning cycle and regular performance forums. | F15: Automated, trusted reporting. Performance information drives decisions and resource allocation. | G15: Real-time, predictive performance insight. Continuous planning and adaptive targets.
... A22: D17 | B22: Change, Transformation & Continuous Improvement | C22: Change managed project by project with no portfolio view. Delivery track record is poor. | D22: PMO established. Methods defined but inconsistently applied; benefits rarely tracked. | E22: Portfolio prioritised against strategy. Standard delivery and change methods; benefits registers maintained. | F22: Portfolio managed dynamically. Change capacity managed and benefits consistently realised. | G22: Continuous transformation capability. Improvement and innovation embedded; the organisation learns and adapts rapidly.

Sheet Stakeholders
A1: Stakeholder Register & Interview Plan
A2: Register everyone to be interviewed or engaged. Engagement approach is derived from influence and interest.
A3: Legend: yellow cells = inputs | grey cells = calculated (do not overwrite) | green text = linked from another tab | grey italic row = example (overwrite or delete)
A5: ID | B5: Name | C5: Role / title | D5: Business unit | E5: Stakeholder group | F5: Influence | G5: Interest | H5: Engagement approach | I5: Dimensions to cover | J5: Interview date | K5: Interviewer | L5: Status | M5: Key themes / notes
A6: Example | B6: Jane Citizen | C6: Chief Operating Officer | D6: Operations | E6: CEO & Executive Leadership | F6: High | G6: High | H6: =IF(OR(F6="",G6=""),"",IF(AND(F6="High",G6="High"),"Manage closely",IF(F6="High","Keep satisfied",IF(G6="High","Keep informed","Monitor")))) -> Manage closely | I6: D04; D06; D07 | J6: 46309 | K6: Lead consultant | L6: Scheduled | M6: Sees cross-unit hand-offs as the main constraint on service times.
A7: S01 | H7: =IF(OR(F7="",G7=""),"",IF(AND(F7="High",G7="High"),"Manage closely",IF(F7="High","Keep satisfied",IF(G7="High","Keep informed","Monitor"))))
A8: S02 | H8: =IF(OR(F8="",G8=""),"",IF(AND(F8="High",G8="High"),"Manage closely",IF(F8="High","Keep satisfied",IF(G8="High","Keep informed","Monitor"))))
A9: S03 | H9: =IF(OR(F9="",G9=""),"",IF(AND(F9="High",G9="High"),"Manage closely",IF(F9="High","Keep satisfied",IF(G9="High","Keep informed","Monitor"))))
A10: S04 | H10: =IF(OR(F10="",G10=""),"",IF(AND(F10="High",G10="High"),"Manage closely",IF(F10="High","Keep satisfied",IF(G10="High","Keep informed","Monitor"))))
A11: S05 | H11: =IF(OR(F11="",G11=""),"",IF(AND(F11="High",G11="High"),"Manage closely",IF(F11="High","Keep satisfied",IF(G11="High","Keep informed","Monitor"))))
A12: S06 | H12: =IF(OR(F12="",G12=""),"",IF(AND(F12="High",G12="High"),"Manage closely",IF(F12="High","Keep satisfied",IF(G12="High","Keep informed","Monitor"))))
A13: S07 | H13: =IF(OR(F13="",G13=""),"",IF(AND(F13="High",G13="High"),"Manage closely",IF(F13="High","Keep satisfied",IF(G13="High","Keep informed","Monitor"))))
A14: S08 | H14: =IF(OR(F14="",G14=""),"",IF(AND(F14="High",G14="High"),"Manage closely",IF(F14="High","Keep satisfied",IF(G14="High","Keep informed","Monitor"))))
A15: S09 | H15: =IF(OR(F15="",G15=""),"",IF(AND(F15="High",G15="High"),"Manage closely",IF(F15="High","Keep satisfied",IF(G15="High","Keep informed","Monitor"))))
A16: S10 | H16: =IF(OR(F16="",G16=""),"",IF(AND(F16="High",G16="High"),"Manage closely",IF(F16="High","Keep satisfied",IF(G16="High","Keep informed","Monitor"))))
A17: S11 | H17: =IF(OR(F17="",G17=""),"",IF(AND(F17="High",G17="High"),"Manage closely",IF(F17="High","Keep satisfied",IF(G17="High","Keep informed","Monitor"))))
A18: S12 | H18: =IF(OR(F18="",G18=""),"",IF(AND(F18="High",G18="High"),"Manage closely",IF(F18="High","Keep satisfied",IF(G18="High","Keep informed","Monitor"))))
... A66: S60 | H66: =IF(OR(F66="",G66=""),"",IF(AND(F66="High",G66="High"),"Manage closely",IF(F66="High","Keep satisfied",IF(G66="High","Keep informed","Monitor"))))

Sheet Interview Guides
A1: Interview Guides
A2: Core questions by stakeholder group, mapped to dimensions. Tailor before each interview and record notes in the yellow column.
A5: Stakeholder group | B5: # | C5: Interview question | D5: Dimensions | E5: Probe / follow-up | F5: Interview notes
A6: Board / Chair | B6: 1 | C6: What are the organisation's most important priorities over the next three to five years, and how confident are you that it can deliver them? | D6: D01 | E6: Which priorities are most at risk, and why?
A7: Board / Chair | B7: 2 | C7: How well does the information the board receives support decisions on strategy, performance and risk? | D7: D07; D10 | E7: What would you like to see more or less of?
A8: Board / Chair | B8: 3 | C8: How clear are the respective roles of the board, its committees and management? | D8: D07 | E8: Any areas where the board is drawn into operational matters?
A9: Board / Chair | B9: 4 | C9: How would you describe the organisation's risk appetite and risk culture? | D9: D15; D09 | E9: Recent examples where appetite shaped a decision.
A10: Board / Chair | B10: 5 | C10: Where do you see the greatest operational, cyber or regulatory exposures? | D10: D15 | E10: How confident are you in the organisation's resilience?
A11: Board / Chair | B11: 6 | C11: How effectively does the organisation deliver major change and realise the promised benefits? | D11: D17 | E11: Recent programs that succeeded or struggled.
A12: Board / Chair | B12: 7 | C12: What would a successful operating model look like to the board in three years? | D12: D01 | E12: How would you know it had been achieved?
A13: CEO & Executive Leadership | B13: 1 | C13: What is the organisation trying to achieve, and what must the operating model do differently to get there? | D13: D01 | E13: What are the non-negotiables?
A14: CEO & Executive Leadership | B14: 2 | C14: What are the biggest barriers to executing the strategy today? | D14: D01; D06; D07 | E14: Are they structural, process, people, technology or cultural?
A15: CEO & Executive Leadership | B15: 3 | C15: Which capabilities are most critical to success, and where are the largest gaps? | D15: D05 | E15: Which capabilities should be built, bought or partnered?
A16: CEO & Executive Leadership | B16: 4 | C16: How are decisions made at the executive level, and where do decisions get stuck? | D16: D07 | E16: Examples of decisions that took too long or were revisited.
A17: CEO & Executive Leadership | B17: 5 | C17: How well do business units and functions work together to deliver end to end for customers? | D17: D06; D09; D02 | E17: Where do hand-offs break down?
... A76: Customers & External Partners | B76: 5 | C76: How does the organisation compare with others you deal with? | D76: D02 | E76: Who does this well?
A77: Customers & External Partners | B77: 6 | C77: What should the organisation start, stop or continue doing? | D77: All
A79: Opening and closing (use in every interview): explain the purpose and confidentiality of the interview; ask the interviewee to describe their role; close by asking 'What have I not asked that I should have?' and 'Who else should we speak to?'.

Sheet Document Requests
A1: Document & Data Request List
A2: Pre-populated with the artefacts typically needed for an operating model assessment. Remove items that do not apply and add client-specific requests at the bottom.
A3: Legend: yellow cells = inputs | grey cells = calculated (do not overwrite) | green text = linked from another tab | grey italic row = example (overwrite or delete)
A5: Ref | B5: Document / artefact | C5: Dimension(s) | D5: Priority | E5: Likely owner | F5: Requested from | G5: Date requested | H5: Date due | I5: Date received | J5: Status | K5: Days outstanding | L5: Notes
A6: DR01 | B6: Strategic plan / corporate plan (current and previous) | C6: D01 | D6: High | E6: CEO office / Strategy | J6: Not requested | K6: =IF(AND(ISNUMBER(G6),NOT(ISNUMBER(I6))),TODAY()-G6,"")
A7: DR02 | B7: Business unit plans | C7: D01; D10 | D7: High | E7: Business unit heads | J7: Not requested | K7: =IF(AND(ISNUMBER(G7),NOT(ISNUMBER(I7))),TODAY()-G7,"")
A8: DR03 | B8: Board and executive committee papers and minutes (last 12 months) | C8: D07 | D8: High | E8: Company Secretary | J8: Not requested | K8: =IF(AND(ISNUMBER(G8),NOT(ISNUMBER(I8))),TODAY()-G8,"")
A9: DR04 | B9: Previous operating model reviews, restructure proposals or consulting reports | C9: D01; D06 | D9: High | E9: Strategy / CEO office | J9: Not requested | K9: =IF(AND(ISNUMBER(G9),NOT(ISNUMBER(I9))),TODAY()-G9,"")
A10: DR05 | B10: ESG / sustainability strategy and report | C10: D01; D15 | D10: Medium | E10: Sustainability lead | J10: Not requested | K10: =IF(AND(ISNUMBER(G10),NOT(ISNUMBER(I10))),TODAY()-G10,"")
A11: DR06 | B11: Customer research, segmentation and NPS / CSAT reports | C11: D02 | D11: High | E11: CX / Marketing | J11: Not requested | K11: =IF(AND(ISNUMBER(G11),NOT(ISNUMBER(I11))),TODAY()-G11,"")
A12: DR07 | B12: Customer journey maps and service blueprints | C12: D02 | D12: Medium | E12: CX lead | J12: Not requested | K12: =IF(AND(ISNUMBER(G12),NOT(ISNUMBER(I12))),TODAY()-G12,"")
A13: DR08 | B13: Complaints register and complaints analysis | C13: D02 | D13: High | E13: Complaints manager | J13: Not requested | K13: =IF(AND(ISNUMBER(G13),NOT(ISNUMBER(I13))),TODAY()-G13,"")
A14: DR09 | B14: Channel volumes and cost by channel | C14: D02; D16 | D14: Medium | E14: Operations / Finance | J14: Not requested | K14: =IF(AND(ISNUMBER(G14),NOT(ISNUMBER(I14))),TODAY()-G14,"")
A15: DR10 | B15: Service charter and customer SLAs | C15: D02; D03 | D15: Medium | E15: Operations | J15: Not requested | K15: =IF(AND(ISNUMBER(G15),NOT(ISNUMBER(I15))),TODAY()-G15,"")
A16: DR11 | B16: Product / service catalogue | C16: D03 | D16: High | E16: Product owners | J16: Not requested | K16: =IF(AND(ISNUMBER(G16),NOT(ISNUMBER(I16))),TODAY()-G16,"")
A17: DR12 | B17: Product performance and P&L reports | C17: D03; D16 | D17: Medium | E17: Finance | J17: Not requested | K17: =IF(AND(ISNUMBER(G17),NOT(ISNUMBER(I17))),TODAY()-G17,"")
... A74: DR69 | B74: Lessons-learned register and post-implementation reviews | C74: D17 | D74: Low | E74: PMO | J74: Not requested | K74: =IF(AND(ISNUMBER(G74),NOT(ISNUMBER(I74))),TODAY()-G74,"")
A75: DR70 | K75: =IF(AND(ISNUMBER(G75),NOT(ISNUMBER(I75))),TODAY()-G75,"")
A76: DR71 | K76: =IF(AND(ISNUMBER(G76),NOT(ISNUMBER(I76))),TODAY()-G76,"")
A77: DR72 | K77: =IF(AND(ISNUMBER(G77),NOT(ISNUMBER(I77))),TODAY()-G77,"")
A78: DR73 | K78: =IF(AND(ISNUMBER(G78),NOT(ISNUMBER(I78))),TODAY()-G78,"")
A79: DR74 | K79: =IF(AND(ISNUMBER(G79),NOT(ISNUMBER(I79))),TODAY()-G79,"")
A80: DR75 | K80: =IF(AND(ISNUMBER(G80),NOT(ISNUMBER(I80))),TODAY()-G80,"")
A81: DR76 | K81: =IF(AND(ISNUMBER(G81),NOT(ISNUMBER(I81))),TODAY()-G81,"")
A82: DR77 | K82: =IF(AND(ISNUMBER(G82),NOT(ISNUMBER(I82))),TODAY()-G82,"")
A83: DR78 | K83: =IF(AND(ISNUMBER(G83),NOT(ISNUMBER(I83))),TODAY()-G83,"")
A84: DR79 | K84: =IF(AND(ISNUMBER(G84),NOT(ISNUMBER(I84))),TODAY()-G84,"")
A85: DR80 | K85: =IF(AND(ISNUMBER(G85),NOT(ISNUMBER(I85))),TODAY()-G85,"")
A86: DR81 | K86: =IF(AND(ISNUMBER(G86),NOT(ISNUMBER(I86))),TODAY()-G86,"")
... A89: DR84 | K89: =IF(AND(ISNUMBER(G89),NOT(ISNUMBER(I89))),TODAY()-G89,"")

Sheet Assessment
A1: Operating Model Maturity Assessment
A2: Score current and target maturity for each question (1–5, or N/A). Importance: 1 = low, 2 = medium, 3 = high. Gap = target − current; weighted gap = gap × importance (shortfalls only).
A3: Legend: yellow cells = inputs | grey cells = calculated (do not overwrite) | green text = linked from another tab | grey italic row = example (overwrite or delete)
A5: ID | B5: Dimension | C5: Sub-component | D5: Assessment question | E5: What good looks like | F5: Importance (1–3) | G5: Current maturity (1–5 / N/A) | H5: Target maturity (1–5) | I5: Gap | J5: Weighted gap | K5: RAG | L5: Evidence confidence | M5: Evidence reviewed / source | N5: Observations & findings | O5: Linked finding ID(s) | P5: Evidence to request | Q5: Key stakeholders
A6: D01 Strategy & Direction | D6: The organisation's purpose, strategic objectives and the explicit choices the operating model must enable.
A7: D01.01 | B7: Strategy & Direction | C7: Purpose & vision | D7: Is there a clearly articulated purpose, vision and mission that is understood across the organisation? | E7: Purpose and vision are documented and current. Staff at all levels can explain them and how their work contributes. | F7: 2 | H7: =Engagement!$C$39 -> 3 | I7: =IF(AND(ISNUMBER(G7),ISNUMBER(H7)),H7-G7,"") | J7: =IF(AND(ISNUMBER(I7),ISNUMBER(F7)),MAX(0,I7)*F7,"") | K7: =IF(ISNUMBER(I7),IF(I7>=Engagement!$C$40,"Red",IF(I7>=Engagement!$C$41,"Amber","Green")),"") | P7: Strategic plan; vision and mission statements; staff engagement survey results | Q7: CEO; Executive team; Frontline staff
A8: D01.02 | B8: Strategy & Direction | C8: Strategic objectives | D8: Are strategic objectives specific, measurable and time-bound, with clear priorities and trade-offs? | E8: A small number of prioritised objectives with measures, targets and owners, plus explicit statements of what the organisation will not do. | F8: 2 | H8: =Engagement!$C$39 -> 3 | I8: =IF(AND(ISNUMBER(G8),ISNUMBER(H8)),H8-G8,"") | J8: =IF(AND(ISNUMBER(I8),ISNUMBER(F8)),MAX(0,I8)*F8,"") | K8: =IF(ISNUMBER(I8),IF(I8>=Engagement!$C$40,"Red",IF(I8>=Engagement!$C$41,"Amber","Green")),"") | P8: Strategic or corporate plan; board papers | Q8: CEO; Executive team; Board
A9: D01.03 | B9: Strategy & Direction | C9: Strategic choices | D9: Has the organisation made explicit choices about where it operates, whom it serves and how it creates value? | E9: Documented choices on target segments, services, channels and sources of advantage that directly inform operating model design. | F9: 2 | H9: =Engagement!$C$39 -> 3 | I9: =IF(AND(ISNUMBER(G9),ISNUMBER(H9)),H9-G9,"") | J9: =IF(AND(ISNUMBER(I9),ISNUMBER(F9)),MAX(0,I9)*F9,"") | K9: =IF(ISNUMBER(I9),IF(I9>=Engagement!$C$40,"Red",IF(I9>=Engagement!$C$41,"Amber","Green")),"") | P9: Strategy documents; market analysis; business cases | Q9: CEO; Strategy lead
A10: D01.04 | B10: Strategy & Direction | C10: External environment | D10: Does the strategy reflect a current understanding of the external environment (market, regulatory, technology, economic, social)? | E10: Regular environmental scanning (e.g. PESTLE) feeds strategy refresh. Emerging regulatory and technology changes are anticipated. | F10: 2 | H10: =Engagement!$C$39 -> 3 | I10: =IF(AND(ISNUMBER(G10),ISNUMBER(H10)),H10-G10,"") | J10: =IF(AND(ISNUMBER(I10),ISNUMBER(F10)),MAX(0,I10)*F10,"") | K10: =IF(ISNUMBER(I10),IF(I10>=Engagement!$C$40,"Red",IF(I10>=Engagement!$C$41,"Amber","Green")),"") | P10: PESTLE / SWOT analyses; horizon-scanning reports; regulatory change updates | Q10: Strategy lead; Risk & Compliance
A11: D01.05 | B11: Strategy & Direction | C11: Design principles | D11: Are there agreed operating model design principles that guide how the organisation is structured and operates? | E11: Six to ten principles (e.g. 'customer first', 'standardise unless differentiating', 'digital by default') endorsed by the executive and used to test design decisions. | F11: 2 | H11: =Engagement!$C$39 -> 3 | I11: =IF(AND(ISNUMBER(G11),ISNUMBER(H11)),H11-G11,"") | J11: =IF(AND(ISNUMBER(I11),ISNUMBER(F11)),MAX(0,I11)*F11,"") | K11: =IF(ISNUMBER(I11),IF(I11>=Engagement!$C$40,"Red",IF(I11>=Engagement!$C$41,"Amber","Green")),"") | P11: Operating model documentation; design principles; executive decisions | Q11: Executive team; COO
A12: D01.06 | B12: Strategy & Direction | C12: Strategy to execution | D12: Is there a clear line of sight from strategy to portfolios, business plans, budgets and individual objectives? | E12: Strategy cascades into business unit plans, the investment portfolio, budgets and individual performance plans with traceable links. | F12: 2 | H12: =Engagement!$C$39 -> 3 | I12: =IF(AND(ISNUMBER(G12),ISNUMBER(H12)),H12-G12,"") | J12: =IF(AND(ISNUMBER(I12),ISNUMBER(F12)),MAX(0,I12)*F12,"") | K12: =IF(ISNUMBER(I12),IF(I12>=Engagement!$C$40,"Red",IF(I12>=Engagement!$C$41,"Amber","Green")),"") | P12: Business unit plans; portfolio register; budget; performance agreements | Q12: Executive team; PMO; Finance
A13: D01.07 | B13: Strategy & Direction | C13: Strategy communication | D13: How effectively is the strategy communicated to, and understood by, staff, partners and other stakeholders? | E13: Structured communication plan. Staff can articulate strategic priorities; progress is discussed through regular two-way engagement. | F13: 2 | H13: =Engagement!$C$39 -> 3 | I13: =IF(AND(ISNUMBER(G13),ISNUMBER(H13)),H13-G13,"") | J13: =IF(AND(ISNUMBER(I13),ISNUMBER(F13)),MAX(0,I13)*F13,"") | K13: =IF(ISNUMBER(I13),IF(I13>=Engagement!$C$40,"Red",IF(I13>=Engagement!$C$41,"Amber","Green")),"") | P13: Internal communication plans; intranet content; engagement survey | Q13: Communications; Frontline staff
A14: D01.08 | B14: Strategy & Direction | C14: Strategy review | D14: Is progress against the strategy reviewed regularly and the strategy adjusted in response to performance and change? | E14: Quarterly strategy reviews by the executive and board, with documented adjustments and re-prioritisation. | F14: 2 | H14: =Engagement!$C$39 -> 3 | I14: =IF(AND(ISNUMBER(G14),ISNUMBER(H14)),H14-G14,"") | J14: =IF(AND(ISNUMBER(I14),ISNUMBER(F14)),MAX(0,I14)*F14,"") | K14: =IF(ISNUMBER(I14),IF(I14>=Engagement!$C$40,"Red",IF(I14>=Engagement!$C$41,"Amber","Green")),"") | P14: Board and executive minutes; strategy performance reports | Q14: CEO; Board; Strategy lead
A15: D01.09 | B15: Strategy & Direction | C15: Sustainability & ESG | D15: Are sustainability, ESG and social-licence considerations embedded in the strategy? | E15: ESG objectives integrated into the strategy with measures. Climate-related risks and opportunities identified and disclosed where required. | F15: 2 | H15: =Engagement!$C$39 -> 3 | I15: =IF(AND(ISNUMBER(G15),ISNUMBER(H15)),H15-G15,"") | J15: =IF(AND(ISNUMBER(I15),ISNUMBER(F15)),MAX(0,I15)*F15,"") | K15: =IF(ISNUMBER(I15),IF(I15>=Engagement!$C$40,"Red",IF(I15>=Engagement!$C$41,"Amber","Green")),"") | P15: ESG / sustainability strategy; climate risk assessment; annual report | Q15: CEO; CFO; Sustainability lead
A16: D02 Customers, Channels & Value Proposition | D16: Who the organisation serves, what value it offers each segment, and how customers access and experience its services.
A17: D02.01 | B17: Customers, Channels & Value Proposition | C17: Customer segments | D17: Are customer or stakeholder segments clearly defined, with an understanding of their needs and value? | E17: Evidence-based segmentation describing the needs, behaviours, value and cost to serve of each segment. | F17: 2 | H17: =Engagement!$C$39 -> 3 | I17: =IF(AND(ISNUMBER(G17),ISNUMBER(H17)),H17-G17,"") | J17: =IF(AND(ISNUMBER(I17),ISNUMBER(F17)),MAX(0,I17)*F17,"") | K17: =IF(ISNUMBER(I17),IF(I17>=Engagement!$C$40,"Red",IF(I17>=Engagement!$C$41,"Amber","Green")),"") | P17: Segmentation studies; customer research; CRM analysis | Q17: Customer / Marketing lead; Product owners
A18: D02.02 | B18: Customers, Channels & Value Proposition | C18: Value proposition | D18: Is the value proposition for each segment clearly articulated and differentiated? | E18: Documented value propositions per segment, tested with customers and reflected in services and channels. | F18: 2 | H18: =Engagement!$C$39 -> 3 | I18: =IF(AND(ISNUMBER(G18),ISNUMBER(H18)),H18-G18,"") | J18: =IF(AND(ISNUMBER(I18),ISNUMBER(F18)),MAX(0,I18)*F18,"") | K18: =IF(ISNUMBER(I18),IF(I18>=Engagement!$C$40,"Red",IF(I18>=Engagement!$C$41,"Amber","Green")),"") | P18: Value proposition documents; brand strategy; customer research | Q18: Executive team; Marketing
A19: D02.03 | B19: Customers, Channels & Value Proposition | C19: Customer journeys | D19: Have the key end-to-end customer journeys been mapped, including pain points and moments that matter? | E19: Priority journeys mapped from the customer's perspective, with pain points quantified and owners assigned. | F19: 2 | H19: =Engagement!$C$39 -> 3 | I19: =IF(AND(ISNUMBER(G19),ISNUMBER(H19)),H19-G19,"") | J19: =IF(AND(ISNUMBER(I19),ISNUMBER(F19)),MAX(0,I19)*F19,"") | K19: =IF(ISNUMBER(I19),IF(I19>=Engagement!$C$40,"Red",IF(I19>=Engagement!$C$41,"Amber","Green")),"") | P19: Journey maps; service blueprints; complaints analysis | Q19: CX lead; Operations managers
A20: D02.04 | B20: Customers, Channels & Value Proposition | C20: Channel strategy | D20: Is there a deliberate channel strategy (digital, phone, face-to-face, partner) aligned to customer needs and cost to serve? | E20: Channel roles defined by segment and interaction type; digital first where appropriate; consistent experience across channels. | F20: 2 | H20: =Engagement!$C$39 -> 3 | I20: =IF(AND(ISNUMBER(G20),ISNUMBER(H20)),H20-G20,"") | J20: =IF(AND(ISNUMBER(I20),ISNUMBER(F20)),MAX(0,I20)*F20,"") | K20: =IF(ISNUMBER(I20),IF(I20>=Engagement!$C$40,"Red",IF(I20>=Engagement!$C$41,"Amber","Green")),"") | P20: Channel strategy; channel volume and cost data; digital analytics | Q20: CX lead; Digital lead; Contact centre manager
A21: D02.05 | B21: Customers, Channels & Value Proposition | C21: Omnichannel consistency | D21: Do customers receive a consistent experience and consistent information across channels? | E21: Single view of the customer and a shared knowledge base across channels. Customers do not need to repeat themselves. | F21: 2 | H21: =Engagement!$C$39 -> 3 | I21: =IF(AND(ISNUMBER(G21),ISNUMBER(H21)),H21-G21,"") | J21: =IF(AND(ISNUMBER(I21),ISNUMBER(F21)),MAX(0,I21)*F21,"") | K21: =IF(ISNUMBER(I21),IF(I21>=Engagement!$C$40,"Red",IF(I21>=Engagement!$C$41,"Amber","Green")),"") | P21: CRM architecture; knowledge management system; mystery shopping results | Q21: Contact centre; Digital; IT
A22: D02.06 | B22: Customers, Channels & Value Proposition | C22: Voice of customer | D22: Are customer feedback, complaints and satisfaction systematically captured, analysed and acted upon? | E22: Closed-loop voice-of-customer program (NPS / CSAT / CES) with root-cause analysis and evidence of changes made. | F22: 2 | H22: =Engagement!$C$39 -> 3 | I22: =IF(AND(ISNUMBER(G22),ISNUMBER(H22)),H22-G22,"") | J22: =IF(AND(ISNUMBER(I22),ISNUMBER(F22)),MAX(0,I22)*F22,"") | K22: =IF(ISNUMBER(I22),IF(I22>=Engagement!$C$40,"Red",IF(I22>=Engagement!$C$41,"Amber","Green")),"") | P22: VoC reports; complaints register; NPS / CSAT trends | Q22: CX lead; Complaints manager
A23: D02.07 | B23: Customers, Channels & Value Proposition | C23: Service standards | D23: Are customer service standards and commitments defined, published and measured? | E23: Published service charter or SLAs, with performance reported and remediation when targets are missed. | F23: 2 | H23: =Engagement!$C$39 -> 3 | I23: =IF(AND(ISNUMBER(G23),ISNUMBER(H23)),H23-G23,"") | J23: =IF(AND(ISNUMBER(I23),ISNUMBER(F23)),MAX(0,I23)*F23,"") | K23: =IF(ISNUMBER(I23),IF(I23>=Engagement!$C$40,"Red",IF(I23>=Engagement!$C$41,"Amber","Green")),"") | P23: Service charter; SLA performance reports | Q23: Operations managers; CX lead
A24: D02.08 | B24: Customers, Channels & Value Proposition | C24: Customer insight | D24: Does the organisation use customer data and insight to design and improve services? | E24: Customer analytics informs product, service and channel decisions; insights are shared across teams. | F24: 2 | H24: =Engagement!$C$39 -> 3 | I24: =IF(AND(ISNUMBER(G24),ISNUMBER(H24)),H24-G24,"") | J24: =IF(AND(ISNUMBER(I24),ISNUMBER(F24)),MAX(0,I24)*F24,"") | K24: =IF(ISNUMBER(I24),IF(I24>=Engagement!$C$40,"Red",IF(I24>=Engagement!$C$41,"Amber","Green")),"") | P24: Analytics reports; insight packs | Q24: Data & Analytics; Marketing
A25: D02.09 | B25: Customers, Channels & Value Proposition | C25: Accessibility & inclusion | D25: Are services accessible and inclusive for all customer groups, including customers experiencing vulnerability? | E25: Accessibility standards (e.g. WCAG 2.2 AA) met; vulnerable customer policy in place; inclusive design practised. | F25: 2 | H25: =Engagement!$C$39 -> 3 | I25: =IF(AND(ISNUMBER(G25),ISNUMBER(H25)),H25-G25,"") | J25: =IF(AND(ISNUMBER(I25),ISNUMBER(F25)),MAX(0,I25)*F25,"") | K25: =IF(ISNUMBER(I25),IF(I25>=Engagement!$C$40,"Red",IF(I25>=Engagement!$C$41,"Amber","Green")),"") | P25: Accessibility audits; vulnerable customer policy | Q25: CX lead; Digital; Legal
A26: D03 Products & Services | D26: The portfolio of products and services the organisation delivers, and how that portfolio is owned, managed and evolved.
A27: D03.01 | B27: Products & Services | C27: Service catalogue | D27: Is there a complete, current catalogue of the products and services the organisation delivers (external and internal)? | E27: A single authoritative catalogue with owners, descriptions, customers, channels and service levels. | F27: 2 | H27: =Engagement!$C$39 -> 3 | I27: =IF(AND(ISNUMBER(G27),ISNUMBER(H27)),H27-G27,"") | J27: =IF(AND(ISNUMBER(I27),ISNUMBER(F27)),MAX(0,I27)*F27,"") | K27: =IF(ISNUMBER(I27),IF(I27>=Engagement!$C$40,"Red",IF(I27>=Engagement!$C$41,"Amber","Green")),"") | P27: Product / service catalogue; internal service catalogue | Q27: Product owners; Operations
A28: D03.02 | B28: Products & Services | C28: Portfolio performance | D28: Is the performance, value or profitability of each product or service known? | E28: Revenue or value, cost, volumes and customer outcomes tracked for each product or service. | F28: 2 | H28: =Engagement!$C$39 -> 3 | I28: =IF(AND(ISNUMBER(G28),ISNUMBER(H28)),H28-G28,"") | J28: =IF(AND(ISNUMBER(I28),ISNUMBER(F28)),MAX(0,I28)*F28,"") | K28: =IF(ISNUMBER(I28),IF(I28>=Engagement!$C$40,"Red",IF(I28>=Engagement!$C$41,"Amber","Green")),"") | P28: Product P&Ls; product performance reports | Q28: CFO; Product owners
A29: D03.03 | B29: Products & Services | C29: Product ownership | D29: Does every product or service have an accountable owner with end-to-end responsibility? | E29: Named owners accountable for outcomes, lifecycle and performance. | F29: 2 | H29: =Engagement!$C$39 -> 3 | I29: =IF(AND(ISNUMBER(G29),ISNUMBER(H29)),H29-G29,"") | J29: =IF(AND(ISNUMBER(I29),ISNUMBER(F29)),MAX(0,I29)*F29,"") | K29: =IF(ISNUMBER(I29),IF(I29>=Engagement!$C$40,"Red",IF(I29>=Engagement!$C$41,"Amber","Green")),"") | P29: Role descriptions; product governance documents | Q29: Product owners; Executive team
A30: D03.04 | B30: Products & Services | C30: Lifecycle management | D30: Is there a defined lifecycle process for designing, launching, changing and retiring products and services? | E30: Stage-gated lifecycle with criteria for launch, review and retirement, applied consistently. | F30: 2 | H30: =Engagement!$C$39 -> 3 | I30: =IF(AND(ISNUMBER(G30),ISNUMBER(H30)),H30-G30,"") | J30: =IF(AND(ISNUMBER(I30),ISNUMBER(F30)),MAX(0,I30)*F30,"") | K30: =IF(ISNUMBER(I30),IF(I30>=Engagement!$C$40,"Red",IF(I30>=Engagement!$C$41,"Amber","Green")),"") | P30: Product lifecycle process; product committee minutes | Q30: Product owners; Risk
A31: D03.05 | B31: Products & Services | C31: Portfolio complexity | D31: Is portfolio complexity actively managed (e.g. overlapping, legacy or low-value products rationalised)? | E31: Periodic rationalisation reviews. The cost of complexity is understood; legacy products are migrated or retired. | F31: 2 | H31: =Engagement!$C$39 -> 3 | I31: =IF(AND(ISNUMBER(G31),ISNUMBER(H31)),H31-G31,"") | J31: =IF(AND(ISNUMBER(I31),ISNUMBER(F31)),MAX(0,I31)*F31,"") | K31: =IF(ISNUMBER(I31),IF(I31>=Engagement!$C$40,"Red",IF(I31>=Engagement!$C$41,"Amber","Green")),"") | P31: Rationalisation reviews; product counts over time | Q31: Product owners; Finance
A32: D03.06 | B32: Products & Services | C32: Innovation pipeline | D32: Is there a pipeline of new or improved products and services linked to strategy and customer insight? | E32: Managed pipeline with prioritisation criteria, a test-and-learn approach and clear funding. | F32: 2 | H32: =Engagement!$C$39 -> 3 | I32: =IF(AND(ISNUMBER(G32),ISNUMBER(H32)),H32-G32,"") | J32: =IF(AND(ISNUMBER(I32),ISNUMBER(F32)),MAX(0,I32)*F32,"") | K32: =IF(ISNUMBER(I32),IF(I32>=Engagement!$C$40,"Red",IF(I32>=Engagement!$C$41,"Amber","Green")),"") | P32: Innovation pipeline; business cases | Q32: Strategy; Product
A33: D03.07 | B33: Products & Services | C33: Pricing & funding | D33: Are pricing, fees or funding arrangements for services understood, justified and reviewed? | E33: Pricing and funding models linked to cost-to-serve and value, and reviewed at least annually. | F33: 2 | H33: =Engagement!$C$39 -> 3 | I33: =IF(AND(ISNUMBER(G33),ISNUMBER(H33)),H33-G33,"") | J33: =IF(AND(ISNUMBER(I33),ISNUMBER(F33)),MAX(0,I33)*F33,"") | K33: =IF(ISNUMBER(I33),IF(I33>=Engagement!$C$40,"Red",IF(I33>=Engagement!$C$41,"Amber","Green")),"") | P33: Pricing policy; funding agreements | Q33: CFO; Product owners
A34: D03.08 | B34: Products & Services | C34: Product obligations | D34: Are product-related regulatory obligations (e.g. consumer law, design and distribution) identified and met? | E34: Obligations mapped to each product with controls and monitoring (e.g. target market determinations where applicable). | F34: 2 | H34: =Engagement!$C$39 -> 3 | I34: =IF(AND(ISNUMBER(G34),ISNUMBER(H34)),H34-G34,"") | J34: =IF(AND(ISNUMBER(I34),ISNUMBER(F34)),MAX(0,I34)*F34,"") | K34: =IF(ISNUMBER(I34),IF(I34>=Engagement!$C$40,"Red",IF(I34>=Engagement!$C$41,"Amber","Green")),"") | P34: Obligations register; product compliance reviews | Q34: Risk & Compliance; Legal
A35: D04 Value Streams & Processes | D35: The end-to-end value streams and business processes through which work flows to deliver outcomes.
A36: D04.01 | B36: Value Streams & Processes | C36: Value streams | D36: Have the organisation's end-to-end value streams been identified (e.g. request-to-resolve, procure-to-pay, hire-to-retire)? | E36: Value streams defined from trigger to outcome, with stages, stakeholders and value items. | F36: 2 | H36: =Engagement!$C$39 -> 3 | I36: =IF(AND(ISNUMBER(G36),ISNUMBER(H36)),H36-G36,"") | J36: =IF(AND(ISNUMBER(I36),ISNUMBER(F36)),MAX(0,I36)*F36,"") | K36: =IF(ISNUMBER(I36),IF(I36>=Engagement!$C$40,"Red",IF(I36>=Engagement!$C$41,"Amber","Green")),"") | P36: Value stream maps; business architecture artefacts | Q36: COO; Business architect
A37: D04.02 | B37: Value Streams & Processes | C37: Process architecture | D37: Is there a structured process architecture (Level 0 to Level 3) covering core and supporting processes? | E37: Documented process hierarchy aligned to a reference model (e.g. APQC PCF) and actively maintained. | F37: 2 | H37: =Engagement!$C$39 -> 3 | I37: =IF(AND(ISNUMBER(G37),ISNUMBER(H37)),H37-G37,"") | J37: =IF(AND(ISNUMBER(I37),ISNUMBER(F37)),MAX(0,I37)*F37,"") | K37: =IF(ISNUMBER(I37),IF(I37>=Engagement!$C$40,"Red",IF(I37>=Engagement!$C$41,"Amber","Green")),"") | P37: Process architecture; process repository | Q37: Process owners; BA / process team
A38: D04.03 | B38: Value Streams & Processes | C38: Process ownership | D38: Do end-to-end processes have accountable owners with authority across organisational boundaries? | E38: Named end-to-end process owners with a mandate, performance measures and improvement responsibility. | F38: 2 | H38: =Engagement!$C$39 -> 3 | I38: =IF(AND(ISNUMBER(G38),ISNUMBER(H38)),H38-G38,"") | J38: =IF(AND(ISNUMBER(I38),ISNUMBER(F38)),MAX(0,I38)*F38,"") | K38: =IF(ISNUMBER(I38),IF(I38>=Engagement!$C$40,"Red",IF(I38>=Engagement!$C$41,"Amber","Green")),"") | P38: RACI; role descriptions | Q38: COO; Process owners
A39: D04.04 | B39: Value Streams & Processes | C39: Documentation | D39: Are key processes documented, current and accessible to the people who perform them? | E39: Processes documented in a common notation (e.g. BPMN 2.0) in a central repository with version control and review dates. | F39: 2 | H39: =Engagement!$C$39 -> 3 | I39: =IF(AND(ISNUMBER(G39),ISNUMBER(H39)),H39-G39,"") | J39: =IF(AND(ISNUMBER(I39),ISNUMBER(F39)),MAX(0,I39)*F39,"") | K39: =IF(ISNUMBER(I39),IF(I39>=Engagement!$C$40,"Red",IF(I39>=Engagement!$C$41,"Amber","Green")),"") | P39: Process maps; standard operating procedures; work instructions | Q39: Process owners; Frontline staff
A40: D04.05 | B40: Value Streams & Processes | C40: Standardisation | D40: Are processes standardised across business units and locations where there is no reason for variation? | E40: Common processes adopted by default. Variations are deliberate, justified and documented. | F40: 2 | H40: =Engagement!$C$39 -> 3 | I40: =IF(AND(ISNUMBER(G40),ISNUMBER(H40)),H40-G40,"") | J40: =IF(AND(ISNUMBER(I40),ISNUMBER(F40)),MAX(0,I40)*F40,"") | K40: =IF(ISNUMBER(I40),IF(I40>=Engagement!$C$40,"Red",IF(I40>=Engagement!$C$41,"Amber","Green")),"") | P40: Process comparisons across units; audit findings | Q40: Operations managers
A41: D04.06 | B41: Value Streams & Processes | C41: Efficiency & waste | D41: Are processes efficient, with minimal rework, hand-offs, delays and manual workarounds? | E41: Process performance analysed (cycle time, rework, touchpoints) and waste systematically removed using Lean methods. | F41: 2 | H41: =Engagement!$C$39 -> 3 | I41: =IF(AND(ISNUMBER(G41),ISNUMBER(H41)),H41-G41,"") | J41: =IF(AND(ISNUMBER(I41),ISNUMBER(F41)),MAX(0,I41)*F41,"") | K41: =IF(ISNUMBER(I41),IF(I41>=Engagement!$C$40,"Red",IF(I41>=Engagement!$C$41,"Amber","Green")),"") | P41: Process metrics; time-and-motion studies; workaround inventory | Q41: Operations managers; Frontline staff
...

Sheet Capabilities
A1: Business Capability Assessment
A2: Generic Level 1 / Level 2 capability model — rename, add or remove capabilities to reflect the client. Priority score = importance weight (High 3, Medium 2, Low 1) × maturity shortfall.
A3: Legend: yellow cells = inputs | grey cells = calculated (do not overwrite) | green text = linked from another tab | grey italic row = example (overwrite or delete)
A5: ID | B5: Tier | C5: Level 1 capability | D5: Level 2 capability | E5: Description | F5: Strategic importance | G5: Differentiation | H5: Current maturity (1–5) | I5: Target maturity (1–5) | J5: Gap | K5: Priority score | L5: Capability owner | M5: Key supporting systems | N5: Sourcing model | O5: Observations
A6: C01 | B6: Strategic | C6: Strategy & Planning | D6: Strategy development | E6: Set direction, strategic objectives and choices. | J6: =IF(AND(ISNUMBER(H6),ISNUMBER(I6)),I6-H6,"") | K6: =IFERROR(IF(AND(ISNUMBER(J6),F6<>""),MAX(0,J6)*INDEX(Lists!$AJ$2:$AJ$4,MATCH(F6,Lists!$AI$2:$AI$4,0)),""),"")
A7: C02 | B7: Strategic | C7: Strategy & Planning | D7: Business planning | E7: Translate strategy into business unit plans and targets. | J7: =IF(AND(ISNUMBER(H7),ISNUMBER(I7)),I7-H7,"") | K7: =IFERROR(IF(AND(ISNUMBER(J7),F7<>""),MAX(0,J7)*INDEX(Lists!$AJ$2:$AJ$4,MATCH(F7,Lists!$AI$2:$AI$4,0)),""),"")
A8: C03 | B8: Strategic | C8: Strategy & Planning | D8: Performance management | E8: Measure, report and steer performance against plans. | J8: =IF(AND(ISNUMBER(H8),ISNUMBER(I8)),I8-H8,"") | K8: =IFERROR(IF(AND(ISNUMBER(J8),F8<>""),MAX(0,J8)*INDEX(Lists!$AJ$2:$AJ$4,MATCH(F8,Lists!$AI$2:$AI$4,0)),""),"")
A9: C04 | B9: Strategic | C9: Strategy & Planning | D9: Enterprise architecture & design | E9: Design and govern the business and technology architecture. | J9: =IF(AND(ISNUMBER(H9),ISNUMBER(I9)),I9-H9,"") | K9: =IFERROR(IF(AND(ISNUMBER(J9),F9<>""),MAX(0,J9)*INDEX(Lists!$AJ$2:$AJ$4,MATCH(F9,Lists!$AI$2:$AI$4,0)),""),"")
A10: C05 | B10: Strategic | C10: Governance & Assurance | D10: Corporate governance | E10: Operate the board, committees and delegations. | J10: =IF(AND(ISNUMBER(H10),ISNUMBER(I10)),I10-H10,"") | K10: =IFERROR(IF(AND(ISNUMBER(J10),F10<>""),MAX(0,J10)*INDEX(Lists!$AJ$2:$AJ$4,MATCH(F10,Lists!$AI$2:$AI$4,0)),""),"")
A11: C06 | B11: Strategic | C11: Governance & Assurance | D11: Enterprise risk management | E11: Identify, assess and treat risks within appetite. | J11: =IF(AND(ISNUMBER(H11),ISNUMBER(I11)),I11-H11,"") | K11: =IFERROR(IF(AND(ISNUMBER(J11),F11<>""),MAX(0,J11)*INDEX(Lists!$AJ$2:$AJ$4,MATCH(F11,Lists!$AI$2:$AI$4,0)),""),"")
A12: C07 | B12: Strategic | C12: Governance & Assurance | D12: Compliance management | E12: Identify obligations and monitor compliance. | J12: =IF(AND(ISNUMBER(H12),ISNUMBER(I12)),I12-H12,"") | K12: =IFERROR(IF(AND(ISNUMBER(J12),F12<>""),MAX(0,J12)*INDEX(Lists!$AJ$2:$AJ$4,MATCH(F12,Lists!$AI$2:$AI$4,0)),""),"")
